{"uuid": "17167796-599c-4710-a3e3-b7ffdb73884a", "children": ["1f4801b9-6f0b-4908-aeab-8b58d5b5485d", "71cfd9c2-eaee-471b-b6b1-005219a930f1", "9f6e54c8-6947-40f0-b34a-536d0607051b", "0197c7c7-6692-4ec7-83dd-24ad4c5fe6e1", "1866feeb-b847-4535-ade3-57773dac143f"], "befores": [{"name": "create_routine", "status": "failed", "statusDetails": {"message": "Failed: Fixture \"login_token\" called directly. Fixtures are not meant to be called directly,\nbut are created automatically when test functions request them as parameters.\nSee https://docs.pytest.org/en/stable/explanation/fixtures.html for more information about fixtures, and\nhttps://docs.pytest.org/en/stable/deprecations.html#calling-fixtures-directly about how to update your code.\n", "trace": "  File \"/Library/Frameworks/Python.framework/Versions/3.12/lib/python3.12/site-packages/pluggy/_callers.py\", line 167, in _multicall\n    teardown.throw(outcome._exception)\n  File \"/Library/Frameworks/Python.framework/Versions/3.12/lib/python3.12/site-packages/_pytest/setuponly.py\", line 36, in pytest_fixture_setup\n    return (yield)\n            ^^^^^\n  File \"/Library/Frameworks/Python.framework/Versions/3.12/lib/python3.12/site-packages/pluggy/_callers.py\", line 103, in _multicall\n    res = hook_impl.function(*args)\n          ^^^^^^^^^^^^^^^^^^^^^^^^^\n  File \"/Library/Frameworks/Python.framework/Versions/3.12/lib/python3.12/site-packages/_pytest/fixtures.py\", line 1122, in pytest_fixture_setup\n    result = call_fixture_func(fixturefunc, request, kwargs)\n             ^^^^^^^^^^^^^^^^^^^^^^^^^^^^^^^^^^^^^^^^^^^^^^^\n  File \"/Library/Frameworks/Python.framework/Versions/3.12/lib/python3.12/site-packages/_pytest/fixtures.py\", line 884, in call_fixture_func\n    fixture_result = fixturefunc(**kwargs)\n                     ^^^^^^^^^^^^^^^^^^^^^\n  File \"/Users/alya/shit/tmm/tests/conftest.py\", line 19, in create_routine\n    \"Authorization\": f\"Bearer {login_token()['accessToken']}\",\n                               ^^^^^^^^^^^^^\n  File \"/Library/Frameworks/Python.framework/Versions/3.12/lib/python3.12/site-packages/_pytest/fixtures.py\", line 1151, in result\n    fail(message, pytrace=False)\n  File \"/Library/Frameworks/Python.framework/Versions/3.12/lib/python3.12/site-packages/_pytest/outcomes.py\", line 177, in fail\n    raise Failed(msg=reason, pytrace=pytrace)\n"}, "start": 1717945526217, "stop": 1717945526217}], "start": 1717945526217, "stop": 1717945526335}