{"uuid": "a599965a-a16f-47ce-b063-f859d81c84ee", "children": ["ce789eba-25f2-4905-9732-987ac60ce933", "41d21cea-1d6c-4b82-9fd1-c6087bd2eb2c", "1cd843b2-ff62-445b-8336-049a1af85810", "4546f373-1f1b-4867-abe0-8af48a96898e", "12fd46a1-c054-481b-9aed-1ba107cf68a5"], "befores": [{"name": "create_routine", "status": "failed", "statusDetails": {"message": "Failed: Fixture \"login_token\" called directly. Fixtures are not meant to be called directly,\nbut are created automatically when test functions request them as parameters.\nSee https://docs.pytest.org/en/stable/explanation/fixtures.html for more information about fixtures, and\nhttps://docs.pytest.org/en/stable/deprecations.html#calling-fixtures-directly about how to update your code.\n", "trace": "  File \"/Library/Frameworks/Python.framework/Versions/3.12/lib/python3.12/site-packages/pluggy/_callers.py\", line 167, in _multicall\n    teardown.throw(outcome._exception)\n  File \"/Library/Frameworks/Python.framework/Versions/3.12/lib/python3.12/site-packages/_pytest/setuponly.py\", line 36, in pytest_fixture_setup\n    return (yield)\n            ^^^^^\n  File \"/Library/Frameworks/Python.framework/Versions/3.12/lib/python3.12/site-packages/pluggy/_callers.py\", line 103, in _multicall\n    res = hook_impl.function(*args)\n          ^^^^^^^^^^^^^^^^^^^^^^^^^\n  File \"/Library/Frameworks/Python.framework/Versions/3.12/lib/python3.12/site-packages/_pytest/fixtures.py\", line 1122, in pytest_fixture_setup\n    result = call_fixture_func(fixturefunc, request, kwargs)\n             ^^^^^^^^^^^^^^^^^^^^^^^^^^^^^^^^^^^^^^^^^^^^^^^\n  File \"/Library/Frameworks/Python.framework/Versions/3.12/lib/python3.12/site-packages/_pytest/fixtures.py\", line 884, in call_fixture_func\n    fixture_result = fixturefunc(**kwargs)\n                     ^^^^^^^^^^^^^^^^^^^^^\n  File \"/Users/alya/shit/tmm/tests/conftest.py\", line 19, in create_routine\n    \"Authorization\": f\"Bearer {login_token()['accessToken']}\",\n                               ^^^^^^^^^^^^^\n  File \"/Library/Frameworks/Python.framework/Versions/3.12/lib/python3.12/site-packages/_pytest/fixtures.py\", line 1151, in result\n    fail(message, pytrace=False)\n  File \"/Library/Frameworks/Python.framework/Versions/3.12/lib/python3.12/site-packages/_pytest/outcomes.py\", line 177, in fail\n    raise Failed(msg=reason, pytrace=pytrace)\n"}, "start": 1717945155046, "stop": 1717945155046}], "start": 1717945155046, "stop": 1717945155206}