{"uuid": "d2d39d1f-228a-4c99-9e97-ee69cc7b0166", "children": ["ead19190-1bee-4fc5-b67d-96c5f76a37c2", "42e8f2f4-6c91-4044-a240-1e9daff2917b", "92fe8e9c-5752-43db-8446-5b3da50898e7", "6f55f7b1-c7e6-49ed-8881-50c3b78b7a28", "e6a062db-98a7-4f09-bfb2-29c8ee75fa14"], "befores": [{"name": "create_routine", "status": "failed", "statusDetails": {"message": "Failed: Fixture \"login_token\" called directly. Fixtures are not meant to be called directly,\nbut are created automatically when test functions request them as parameters.\nSee https://docs.pytest.org/en/stable/explanation/fixtures.html for more information about fixtures, and\nhttps://docs.pytest.org/en/stable/deprecations.html#calling-fixtures-directly about how to update your code.\n", "trace": "  File \"/Library/Frameworks/Python.framework/Versions/3.12/lib/python3.12/site-packages/pluggy/_callers.py\", line 167, in _multicall\n    teardown.throw(outcome._exception)\n  File \"/Library/Frameworks/Python.framework/Versions/3.12/lib/python3.12/site-packages/_pytest/setuponly.py\", line 36, in pytest_fixture_setup\n    return (yield)\n            ^^^^^\n  File \"/Library/Frameworks/Python.framework/Versions/3.12/lib/python3.12/site-packages/pluggy/_callers.py\", line 103, in _multicall\n    res = hook_impl.function(*args)\n          ^^^^^^^^^^^^^^^^^^^^^^^^^\n  File \"/Library/Frameworks/Python.framework/Versions/3.12/lib/python3.12/site-packages/_pytest/fixtures.py\", line 1122, in pytest_fixture_setup\n    result = call_fixture_func(fixturefunc, request, kwargs)\n             ^^^^^^^^^^^^^^^^^^^^^^^^^^^^^^^^^^^^^^^^^^^^^^^\n  File \"/Library/Frameworks/Python.framework/Versions/3.12/lib/python3.12/site-packages/_pytest/fixtures.py\", line 884, in call_fixture_func\n    fixture_result = fixturefunc(**kwargs)\n                     ^^^^^^^^^^^^^^^^^^^^^\n  File \"/Users/alya/shit/tmm/tests/conftest.py\", line 19, in create_routine\n    \"Authorization\": f\"Bearer {login_token()['accessToken']}\",\n                               ^^^^^^^^^^^^^\n  File \"/Library/Frameworks/Python.framework/Versions/3.12/lib/python3.12/site-packages/_pytest/fixtures.py\", line 1151, in result\n    fail(message, pytrace=False)\n  File \"/Library/Frameworks/Python.framework/Versions/3.12/lib/python3.12/site-packages/_pytest/outcomes.py\", line 177, in fail\n    raise Failed(msg=reason, pytrace=pytrace)\n"}, "start": 1717945292565, "stop": 1717945292565}], "start": 1717945292565, "stop": 1717945292779}